Workbook

Sheet ЦЕХ
A1: Таблица 1
A2: Электрические нагрузки ремонтно-механического цеха
A3: Исходные данные | H3: Расчетные величины | J3: n*Pн2 | K3: Эффективн. число эл.приемн. nэ | L3: Коэф. расчетной нагрузки Кр | M3: Расчетная мощность | P3: Ток
A4: По заданию технологов | E4: По справочным данным | H4: Активная мощность | I4: Реактивная, | M4: Активная Р мах | N4: Реактивная, Qмах | O4: Полная, Sмах
A5: Наименование ЭП | B5: Кол-воЭП, шт n | C5: Установленная мощность, кВт | E5: Коэффициент использов Ки | F5: соs | G5: tq | R5: Тип ШР: ШР-11
C6: одного ЭП, p | D6: общая Р=n*p | H6: Рпр=Ки*р кВт | I6: Qпр=Ки*р*tg, кВАр | M6: кВт | N6: кВАр | O6: кВА | R6: https://iicom.kz/production/shkafy-raspredeleniya-0-4-kv/shkafy-raspredelitelnye-shr-11-shrs-1/
A7: 2 | B7: 3 | C7: 4 | D7: 5 | E7: 6 | F7: 7 | G7: 9 | H7: 8 | I7: 9 | J7: 10 | K7: 11 | L7: 12 | M7: 13 | N7: 14 | O7: 15 | P7: 16
A8: ШР-2
A9: Токарные автоматы (6-8) | B9: 3 | C9: 15 | D9: =B9*C9 -> 45 | E9: 0.17 | F9: 0.65 | G9: =TAN(ACOS(F9)) -> 1.1691296 | H9: =D9*E9 -> 7.65 | I9: =H9*G9 -> 8.9438411 | J9: =B9*(C9*C9) -> 675
A10: Зубофрезерные станки (9-11) | B10: 3 | C10: 25 | D10: =B10*C10 -> 75 | E10: 0.17 | F10: 0.65 | G10: =TAN(ACOS(F10)) -> 1.1691296 | H10: =D10*E10 -> 12.75 | I10: =H10*G10 -> 14.906402 | J10: =B10*(C10*C10) -> 1875
A11: Круглошлифовальные станки (12-13) | B11: 0 | C11: 0 | D11: =B11*C11 -> 0 | E11: 0 | F11: 0.5 | G11: =TAN(ACOS(F11)) -> 1.7320508 | H11: =D11*E11 -> 0 | I11: =H11*G11 -> 0 | J11: =B11*(C11*C11) -> 0
A12: Итого ШР-1 | B12: =SUM(B9:B11) -> 6 | C12: =SUM(C9:C11) -> 40 | D12: =SUM(D9:D11) -> 120 | E12: =H12/D12 -> 0.17 | F12: =COS(ATAN(G12)) -> 0.65 | G12: =I12/H12 -> 1.1691296 | H12: =SUM(H9:H11) -> 20.4 | I12: =SUM(I9:I11) -> 23.850243 | J12: =SUM(J9:J11) -> 2550 | K12: =POWER(D12, 2)/J12 -> 5.6470588 | L12: 2.84 | M12: =L12*H12 -> 57.936 | N12: =IF(K12>10, I12, 1.1*I12) -> 26.235267 | O12: =SQRT(POWER(M12, 2)+POWER(N12, 2)) -> 63.599287 | P12: =O12/(SQRT(3)*0.4) -> 91.797664
A13: ШР-3
A14: Заточные станки (15-17) | B14: 10 | C14: 21 | D14: =B14*C14 -> 210 | E14: 0.12 | F14: 0.5 | G14: =TAN(ACOS(F14)) -> 1.7320508 | H14: =D14*E14 -> 25.2 | I14: =H14*G14 -> 43.64768 | J14: =B14*(C14*C14) -> 4410 | L14: 55.5
A15: Токарные станки (25) | B15: 3 | C15: 4.5 | D15: =B15*C15 -> 13.5 | E15: 0.12 | F15: 0.5 | G15: =TAN(ACOS(F15)) -> 1.7320508 | H15: =D15*E15 -> 1.62 | I15: =H15*G15 -> 2.8059223 | J15: =B15*(C15*C15) -> 60.75
A16: Плоскошлифовальные станки (26,27) | B16: 0 | C16: 0 | D16: =B16*C16 -> 0 | E16: 0 | F16: 0.5 | G16: =TAN(ACOS(F16)) -> 1.7320508 | H16: =D16*E16 -> 0 | I16: =H16*G16 -> 0 | J16: =B16*(C16*C16) -> 0
A17: Краные мостовые (38) | B17: 0 | C17: 0 | D17: =B17*C17 -> 0 | E17: 0 | F17: 0.5 | G17: =TAN(ACOS(F17)) -> 1.7320508 | H17: =D17*E17 -> 0 | I17: =H17*G17 -> 0 | J17: =B17*(C17*C17) -> 0
A18: Итого ШР-2 | B18: =SUM(B14:B17) -> 13 | C18: =SUM(C14:C17) -> 25.5 | D18: =SUM(D14:D17) -> 223.5 | E18: =H18/D18 -> 0.12 | F18: =COS(ATAN(G18)) -> 0.5 | G18: =I18/H18 -> 1.7320508 | H18: =SUM(H14:H17) -> 26.82 | I18: =SUM(I14:I17) -> 46.453603 | J18: =SUM(J14:J17) -> 4470.75 | K18: =POWER(D18, 2)/J18 -> 11.173125 | L18: 2.84 | M18: =L18*H18 -> 76.1688 | N18: =IF(K18>10, I18, 1.1*I18) -> 46.453603 | O18: =SQRT(POWER(M18, 2)+POWER(N18, 2)) -> 89.216721 | P18: =O18/(SQRT(3)*0.4) -> 128.77324
A19: ШР-4
A20: Токарные станки (20-24) | B20: 3 | C20: 10 | D20: =B20*C20 -> 30 | E20: 0.12 | F20: 0.5 | G20: =TAN(ACOS(F20)) -> 1.7320508 | H20: =D20*E20 -> 3.6 | I20: =H20*G20 -> 6.2353829 | J20: =B20*(C20*C20) -> 300
A21: Сверильные станки (18,19) | B21: 0 | C21: 0 | D21: =B21*C21 -> 0 | E21: 0 | F21: 0.5 | G21: =TAN(ACOS(F21)) -> 1.7320508 | H21: =D21*E21 -> 0 | I21: =H21*G21 -> 0 | J21: =B21*(C21*C21) -> 0
A22: Итого ШР-3 | B22: =SUM(B20:B21) -> 3 | C22: =SUM(C20:C21) -> 10 | D22: =SUM(D20:D21) -> 30 | E22: =H22/D22 -> 0.12 | F22: =COS(ATAN(G22)) -> 0.5 | G22: =I22/H22 -> 1.7320508 | H22: =SUM(H20:H21) -> 3.6 | I22: =SUM(I20:I21) -> 6.2353829 | J22: =SUM(J20:J21) -> 300 | K22: =POWER(D22, 2)/J22 -> 3 | L22: 2.84 | M22: =L22*H22 -> 10.224 | N22: =IF(K22>10, I22, 1.1*I22) -> 6.8589212 | O22: =SQRT(POWER(M22, 2)+POWER(N22, 2)) -> 12.311579 | P22: =O22/(SQRT(3)*0.4) -> 17.770234
A23: ШР-5
A24: Строгальные станки (29-30) | B24: 12 | C24: 17 | D24: =B24*C24 -> 204 | E24: 0.12 | F24: 0.5 | G24: =TAN(ACOS(F24)) -> 1.7320508 | H24: =D24*E24 -> 24.48 | I24: =H24*G24 -> 42.400604 | J24: =B24*(C24*C24) -> 3468
A25: Фрезерные станки (32,34) | B25: 0 | C25: 0 | D25: =B25*C25 -> 0 | E25: 0 | F25: 0.5 | G25: =TAN(ACOS(F25)) -> 1.7320508 | H25: =D25*E25 -> 0 | I25: =H25*G25 -> 0 | J25: =B25*(C25*C25) -> 0
A26: Расточные станки (36-37) | B26: 0 | C26: 0 | D26: =B26*C26 -> 0 | E26: 0 | F26: 0.5 | G26: =TAN(ACOS(F26)) -> 1.7320508 | H26: =D26*E26 -> 0 | I26: =H26*G26 -> 0 | J26: =B26*(C26*C26) -> 0
A27: Итого ШР-4 | B27: =SUM(B24:B26) -> 12 | C27: =SUM(C24:C26) -> 17 | D27: =SUM(D24:D26) -> 204 | E27: =H27/D27 -> 0.12 | F27: =COS(ATAN(G27)) -> 0.5 | G27: =I27/H27 -> 1.7320508 | H27: =SUM(H24:H26) -> 24.48 | I27: =SUM(I24:I26) -> 42.400604 | J27: =SUM(J24:J26) -> 3468 | K27: =POWER(D27, 2)/J27 -> 12 | L27: 2.27 | M27: =L27*H27 -> 55.5696 | N27: =IF(K27>10, I27, 1.1*I27) -> 42.400604 | O27: =SQRT(POWER(M27, 2)+POWER(N27, 2)) -> 69.898438 | P27: =O27/(SQRT(3)*0.4) -> 100.88971
A28: ШР-5
A29: Строгальные станки (28) | B29: 1 | C29: 3.5 | D29: =B29*C29 -> 3.5 | E29: 1 | F29: 0.5 | G29: =TAN(ACOS(F29)) -> 1.7320508 | H29: =D29*E29 -> 3.5 | I29: =H29*G29 -> 6.0621778 | J29: =B29*(C29*C29) -> 12.25
A30: Фрезерные станки (31,33) | B30: 1 | C30: 4.2 | D30: =B30*C30 -> 4.2 | E30: 1 | F30: 0.5 | G30: =TAN(ACOS(F30)) -> 1.7320508 | H30: =D30*E30 -> 4.2 | I30: =H30*G30 -> 7.2746134 | J30: =B30*(C30*C30) -> 17.64
A31: Расточные станки (35) | B31: 1 | C31: 5.3 | D31: =B31*C31 -> 5.3 | E31: 1 | F31: 0.5 | G31: =TAN(ACOS(F31)) -> 1.7320508 | H31: =D31*E31 -> 5.3 | I31: =H31*G31 -> 9.1798693 | J31: =B31*(C31*C31) -> 28.09
A32: Краные мостовые (39) | B32: 1 | C32: 4.3 | D32: =B32*C32 -> 4.3 | E32: 1 | F32: 0.5 | G32: =TAN(ACOS(F32)) -> 1.7320508 | H32: =D32*E32 -> 4.3 | I32: =H32*G32 -> 7.4478185 | J32: =B32*(C32*C32) -> 18.49
A33: Круглошлифовальные станки (14) | B33: 0 | C33: 0 | D33: =B33*C33 -> 0 | E33: 0 | F33: 0.5 | G33: =TAN(ACOS(F33)) -> 1.7320508 | H33: =D33*E33 -> 0 | I33: =H33*G33 -> 0 | J33: =B33*(C33*C33) -> 0
A34: Итого ШР-5 | B34: =SUM(B29:B33) -> 4 | C34: =SUM(C29:C33) -> 17.3 | D34: =SUM(D29:D33) -> 17.3 | E34: =H34/D34 -> 1 | F34: =COS(ATAN(G34)) -> 0.5 | G34: =I34/H34 -> 1.7320508 | H34: =SUM(H29:H33) -> 17.3 | I34: =SUM(I29:I33) -> 29.964479 | J34: =SUM(J29:J33) -> 76.47 | K34: =POWER(D34, 2)/J34 -> 3.9138224 | L34: 2.27 | M34: =L34*H34 -> 39.271 | N34: =IF(K34>10, I34, 1.1*I34) -> 32.960927 | O34: =SQRT(POWER(M34, 2)+POWER(N34, 2)) -> 51.270207 | P34: =O34/(SQRT(3)*0.4) -> 74.00217
A35: РП-1
A36: Вентиляторы (1,2) | B36: 1 | C36: 40 | D36: =B36*C36 -> 40 | E36: 0.6 | F36: 0.8 | G36: =TAN(ACOS(F36)) -> 0.75 | H36: =D36*E36 -> 24 | I36: =H36*G36 -> 18 | J36: =B36*(5.5*5.5) -> 30.25
A37: Вентиляторы (1,2) | B37: 1 | C37: 60 | D37: =B37*C37 -> 60 | E37: 0.6 | F37: 0.6 | G37: =TAN(ACOS(F37)) -> 1.3333333 | H37: =D37*E37 -> 36 | I37: =H37*G37 -> 48 | J37: =B37*(C37*C37) -> 3600
A38: Итого РУ | B38: =SUM(B36:B37) -> 2 | C38: =SUM(C36:C37) -> 100 | D38: =SUM(D36:D37) -> 100 | E38: =H38/D38 -> 0.6 | F38: =COS(ATAN(G38)) -> 0.67267279 | G38: =I38/H38 -> 1.1 | H38: =SUM(H36:H37) -> 60 | I38: =SUM(I36:I37) -> 66 | J38: =SUM(J36:J37) -> 3630.25 | K38: =POWER(D38, 2)/J38 -> 2.7546312 | L38: 1 | M38: =L38*H38 -> 60 | N38: =IF(K38>10, I38, 1.1*I38) -> 72.6 | O38: =SQRT(POWER(M38, 2)+POWER(N38, 2)) -> 94.184712 | P38: =O38/(SQRT(3)*0.4) -> 135.94392
A39: Итого цех | B39: =B12+B18+B22+B27+B34+B38 -> 40 | C39: =C12+C18+C22+C27+C34+C38 -> 209.8 | D39: =D12+D18+D22+D27+D34+D38 -> 694.8 | E39: =H39/D39 -> 0.21963155 | F39: =COS(ATAN(G39)) -> 0.57896717 | G39: =I39/H39 -> 1.4082851 | H39: =H12+H18+H22+H27+H38+H34 -> 152.6 | I39: =I12+I18+I22+I27+I38+I34 -> 214.90431 | J39: =J12+J18+J22+J27+J38+J34 -> 14495.47 | M39: =M12+M18+M22+M27+M38+M34 -> 299.1694 | N39: =N12+N18+N22+N27+N38+N34 -> 227.50932 | O39: =SQRT(POWER(M39, 2)+POWER(N39, 2)) -> 375.84947 | P39: =O39/(SQRT(3)*0.4) -> 542.49198

Sheet СВЕТ
A1: Таблица 3.3
A2: Расчет электрического освещения
A3: N пп | B3: Наименование цеха | C3: Длина А, м | D3: Ширина В, м | E3: Освещеность Е, лк | F3: Тип светильника | G3: Высота Н, м | H3: Руд Вт/м2 | I3: Площадь S, м2 | J3: Кзап | K3: К спроса Кс | L3: Мощность установл.Руст, кВт | M3: Мощность расчетн.активная Ррасч, кВт | N3: Мощность расчетн.реактивная Qрасч, кВАр | O3: Освещенность (%) | P3: Эф. высота | Q3: Руд | R3: Свес | S3: Между светильниками L | T3: От стены l0 | U3: Кол-во | V3: 1 | W3: 2 | X3: Ф | Y3: Ф светильника | Z3: Мощность
A4: 1 | B4: Главный корпус (сборочный цех) | C4: 48 | D4: 48 | E4: 250 | G4: 6 | H4: =Q4 -> 1.99071 | I4: =C4*D4 -> 2304 | J4: 1.3 | K4: 0.7 | L4: =H4*I4/1000 -> 4.586596 | M4: =L4*K4*J4 -> 4.1738023 | N4: =TAN(ACOS(0.9))*M4 -> 2.0214647 | O4: =(Y4-X4)/Y4*100 -> -2.3085541 | P4: =G4-R4-0.8 -> 4.2 | Q4: =Z4*U4/I4 -> 1.99071 | R4: 1 | S4: =2.2*P4 -> 9.24 | T4: =0.8*S4 -> 7.392 | U4: =V4*W4+3 -> 19.51743 | V4: =(C4-2*T4)/S4+1 -> 4.5948052 | W4: =(D4-2*T4)/S4 -> 3.5948052 | X4: =E4*J4*1*C4*D4/(1.5*U4) -> 25577.139 | Y4: 25000 | Z4: 235 | AD4: 13.631918
A5: 2 | B5: Механозборочный цех | C5: 48 | D5: 48 | E5: 200 | G5: 8 | H5: =Q5 -> 3.0974862 | I5: =C5*D5 -> 2304 | J5: 1.3 | K5: 0.7 | L5: =H5*I5/1000 -> 7.1366083 | M5: =L5*K5*J5 -> 6.4943135 | N5: =TAN(ACOS(0.9))*M5 -> 3.1453396 | O5: =(Y5-X5)/Y5*100 -> 1.3716358 | P5: =G5-R5-0.8 -> 6.2 | Q5: =Z5*U5/I5 -> 3.0974862 | R5: 1 | S5: =1.3*P5 -> 8.06 | T5: =0.6*S5 -> 4.836 | U5: =V5*W5+3 -> 30.368546 | V5: =(C5-2*T5)/S5+1 -> 5.755335 | W5: =(D5-2*T5)/S5 -> 4.755335 | X5: =E5*J5*1*C5*D5/(0.8*U5) -> 24657.091 | Y5: 25000 | Z5: 235 | AD5: 14.353075
A6: 3 | B6: Литейный цех | C6: 36 | D6: 54 | E6: 200 | G6: 8 | H6: =Q6 -> 3.5750197 | I6: =C6*D6 -> 1944 | J6: 1.3 | K6: 0.7 | L6: =H6*I6/1000 -> 6.9498382 | M6: =L6*K6*J6 -> 6.3243528 | N6: =TAN(ACOS(0.9))*M6 -> 3.0630238 | O6: =(Y6-X6)/Y6*100 -> 8.8489859 | P6: =G6-R6-0.6 -> 6.4 | Q6: =Z6*U6/I6 -> 3.5750197 | R6: 1 | S6: =1.3*P6 -> 8.32 | T6: =0.5*S6 -> 4.16 | U6: =V6*W6-5 -> 29.57378 | V6: =(C6-2*T6)/S6+2 -> 5.3269231 | W6: =(D6-2*T6)/S6+1 -> 6.4903846 | X6: =E6*J6*1*C6*D6/(0.75*U6) -> 22787.754 | Y6: 25000 | Z6: 235 | AD6: 9.196
A7: 4 | B7: Компрессорная станция | C7: 24 | D7: 60 | E7: 100 | G7: 10 | H7: =Q7 -> 2.082094 | I7: =C7*D7 -> 1440 | J7: 1.5 | K7: 0.55 | L7: =H7*I7/1000 -> 2.9982153 | M7: =L7*K7*J7 -> 2.4735277 | N7: =TAN(ACOS(0.9))*M7 -> 1.1979841 | O7: =(Y7-X7)/Y7*100 -> 9.9464286 | P7: =G7-R7-0.8 -> 8.2 | Q7: =Z7*U7/I7 -> 2.082094 | R7: 1 | S7: =1*P7 -> 8.2 | T7: =0.5*S7 -> 4.1 | U7: =V7*W7 -> 21.415824 | V7: =(C7-2*T7)/S7+1 -> 2.9268293 | W7: =(D7-2*T7)/S7+1 -> 7.3170732 | X7: =E7*J7*1*C7*D7/(0.8*(V7*W7)) -> 12607.5 | Y7: 14000 | Z7: 140 | AD7: 8.8445388
A8: 5 | B8: Котельная станция | C8: 36 | D8: 48 | E8: 100 | G8: 8 | H8: =Q8 -> 2.0572917 | I8: =C8*D8 -> 1728 | J8: 1.5 | K8: 0.6 | L8: =H8*I8/1000 -> 3.555 | M8: =L8*K8*J8 -> 3.1995 | N8: =TAN(ACOS(0.9))*M8 -> 1.5495886 | O8: =(Y8-X8)/Y8*100 -> -3.9398496 | P8: =G8-R8-0.6 -> 6.4 | Q8: =Z8*U8/I8 -> 2.0572917 | R8: 1 | S8: =1.5*P8 -> 9.6 | T8: =0.5*S8 -> 4.8 | U8: =V8*W8+1 -> 19.75 | V8: =(C8-2*T8)/S8+1 -> 3.75 | W8: =(D8-2*T8)/S8+1 -> 5 | X8: =E8*J8*1*C8*D8/(0.7*(V8*W8)) -> 19748.571 | Y8: 19000 | Z8: 180 | AD8: 24.0768 | AH8: Светильники
A9: 6 | B9: Кузнечно-прессовый цех | C9: 36 | D9: 54 | E9: 200 | G9: 6 | H9: =Q9 -> 2.401466 | I9: =C9*D9 -> 1944 | J9: 1.3 | K9: 0.6 | L9: =H9*I9/1000 -> 4.6684499 | M9: =L9*K9*J9 -> 3.6413909 | N9: =TAN(ACOS(0.9))*M9 -> 1.7636061 | O9: =(Y9-X9)/Y9*100 -> 2.7804734 | P9: =G9-R9-0.4 -> 4.6 | Q9: =Z9*U9/I9 -> 2.401466 | R9: 1 | S9: =1.5*P9 -> 6.9 | T9: =0.5*S9 -> 3.45 | U9: =V9*W9 -> 42.440454 | V9: =(C9-2*T9)/S9+2 -> 6.2173913 | W9: =(D9-2*T9)/S9 -> 6.826087 | X9: =E9*J9*1*C9*D9/(0.7*(V9*W9)) -> 17013.417 | Y9: 17500 | Z9: 110 | AB9: ` | AD9: 11.5368 | AH9: 1 | AI9: https://terra-led.kz/svetilniki_armstrong_600x600/svetilnik-svetodiodnyy-armstrong-35vt-3500lm-ip54-1/
A10: 7 | B10: Ремонтно-механический цех | C10: 60 | D10: 48 | E10: 200 | G10: 10 | H10: =Q10 -> 2.2492515 | I10: =C10*D10 -> 2880 | J10: 1.3 | K10: 0.3 | L10: =H10*I10/1000 -> 6.4778443 | M10: =L10*K10*J10 -> 2.5263593 | N10: =TAN(ACOS(0.9))*M10 -> 1.2235716 | O10: =(Y10-X10)/Y10*100 -> -4.9290873 | P10: =G10-R10-0.8 -> 8.2 | Q10: =Z10*U10/I10 -> 2.2492515 | R10: 1 | S10: =1.1*P10 -> 9.02 | T10: =0.5*S10 -> 4.51 | U10: =V10*W10 -> 35.398056 | V10: =(C10-2*T10)/S10+1 -> 6.6518847 | W10: =(D10-2*T10)/S10+1 -> 5.3215078 | X10: =E10*J10*1*C10*D10/(0.8*(V10*W10)) -> 26442.13 | Y10: 25200 | Z10: 183 | AD10: 46.1472 | AH10: 2 | AI10: https://diode-system.com/ds-street-lv-150.html
A11: 8 | B11: Термический цех | C11: 36 | D11: 48 | E11: 150 | G11: 3 | H11: =Q11 -> 0.90534979 | I11: 3888 | J11: 1.1 | K11: 0.85 | L11: =H11*I11/1000 -> 3.52 | M11: =L11*K11*J11 -> 3.2912 | N11: =TAN(ACOS(0.9))*M11 -> 1.5940009 | O11: =(Y11-X11)/Y11*100 -> -7.3291925 | P11: =G11-R11-1 -> 2 | Q11: =Z11*U11/I11 -> 0.90534979 | R11: 0 | S11: =2.5*P11 -> 5 | T11: =1.3*S11 -> 6.5 | U11: =V11*W11+3 -> 35.2 | V11: =(C11-2*T11)/S11 -> 4.6 | W11: =(D11-2*T11)/S11 -> 7 | X11: =E11*J11*1*C11*D11/(0.75*(V11*W11)) -> 11806.211 | Y11: 11000 | Z11: 100 | AD11: 29.534208 | AH11: 3 | AI11: https://diode-system.com/ds-street-83.html
A12: 9 | B12: Насосная станция | C12: 48 | D12: 24 | E12: 100 | G12: 8 | H12: =Q12 -> 2.2919132 | I12: =C12*D12 -> 1152 | J12: 1.3 | K12: 0.3 | L12: =H12*I12/1000 -> 2.640284 | M12: =L12*K12*J12 -> 1.0297108 | N12: =TAN(ACOS(0.9))*M12 -> 0.49871169 | O12: =(Y12-X12)/Y12*100 -> 7.8584535 | P12: =G12-R12-1 -> 5 | Q12: =Z12*U12/I12 -> 2.2919132 | R12: 2 | S12: =1.3*P12 -> 6.5 | T12: =0.5*S12 -> 3.25 | U12: =V12*W12+1 -> 23.573964 | V12: =(C12-2*T12)/S12+2 -> 8.3846154 | W12: =(D12-2*T12)/S12 -> 2.6923077 | X12: =E12*J12*1*C12*D12/(0.8*(V12*W12)) -> 8292.7392 | Y12: 9000 | Z12: 112 | AD12: 6.861888 | AH12: 4 | AI12: https://diode-system.com/ds-street-83.html
A13: 10 | B13: Заготовительно-сварочный цех | C13: 48 | D13: 24 | E13: 150 | G13: 8 | H13: =Q13 -> 1.9207986 | I13: =C13*D13 -> 1152 | J13: 1.5 | K13: 0.85 | L13: =H13*I13/1000 -> 2.21276 | M13: =L13*K13*J13 -> 2.821269 | N13: =TAN(ACOS(0.9))*M13 -> 1.3664029 | O13: =(Y13-X13)/Y13*100 -> -9.4594595 | P13: =G13-R13-1 -> 5 | Q13: =Z13*U13/I13 -> 1.9207986 | R13: 2 | S13: =1.5*P13 -> 7.5 | T13: =0.5*S13 -> 3.75 | U13: =V13*W13-3 -> 20.68 | V13: =(C13-2*T13)/S13+2 -> 7.4 | W13: =(D13-2*T13)/S13+1 -> 3.2 | X13: =E13*J13*1*C13*D13/(0.8*(V13*W13)) -> 13682.432 | Y13: 12500 | Z13: 107 | AD13: 102.9952 | AH13: 5 | AI13: https://diode-system.com/ds-street-60.html
A14: 11 | B14: Склад | C14: 48 | D14: 24 | E14: 75 | G14: 8 | H14: =Q14 -> 0.38821373 | I14: =C14*D14 -> 1152 | J14: 1.5 | K14: 0.5 | L14: =H14*I14/1000 -> 0.44722222 | M14: =L14*K14*J14 -> 0.33541667 | N14: =TAN(ACOS(0.9))*M14 -> 0.16244971 | O14: =(Y14-X14)/Y14*100 -> -8.907563 | P14: =G14-R14-1 -> 6 | Q14: =Z14*U14/I14 -> 0.38821373 | R14: 1 | S14: =1.2*P14 -> 7.2 | T14: =0.5*S14 -> 3.6 | U14: =V14*W14-1 -> 17.888889 | V14: =(C14-2*T14)/S14 -> 5.6666667 | W14: =(D14-2*T14)/S14+1 -> 3.3333333 | X14: =E14*J14*1*C14*D14/(1.4*(V14*W14)) -> 4900.8403 | Y14: 4500 | Z14: 25 | AD14: 32.757551 | AH14: 6 | AI14: https://akvilon.kz/p/svetilnik-svetodiodnyy-wlfs45w04-45-vt-1500-mm-4000k-5000-lm-dnevnoy-belyy-wolta-99911116/
A15: 12 | B15: Админс бытовой корпус | C15: 24 | D15: 24 | E15: 250 | G15: 9 | H15: =Q15 -> 2.1486169 | I15: =C15*D15 -> 576 | J15: 1.5 | K15: 0.5 | L15: =H15*I15/1000 -> 1.2376033 | M15: =L15*K15*J15 -> 0.92820248 | N15: =TAN(ACOS(0.9))*M15 -> 0.44954898 | O15: =(Y15-X15)/Y15*100 -> -10 | P15: =G15-R15-2 -> 4 | Q15: =Z15*U15/I15 -> 2.1486169 | R15: 3 | S15: =1.1*P15 -> 4.4 | T15: =0.5*S15 -> 2.2 | U15: =V15*W15-5 -> 24.752066 | V15: =(C15-2*T15)/S15+1 -> 5.4545455 | W15: =(D15-2*T15)/S15+1 -> 5.4545455 | X15: =E15*J15*1*C15*D15/(1.2*(V15*W15)) -> 6050 | Y15: 5500 | Z15: 50 | AH15: 7 | AI15: https://diode-system.com/ds-street-lv-150.html
A16: 13 | B16: Транспортный цех | C16: 24 | D16: 48 | E16: 150 | G16: 10 | H16: =Q16 -> 3.85 | I16: =C16*D16 -> 1152 | J16: 1.5 | K16: 0.5 | L16: =H16*I16/1000 -> 4.4352 | M16: =L16*K16*J16 -> 3.3264 | N16: =TAN(ACOS(0.9))*M16 -> 1.611049 | O16: =(Y16-X16)/Y16*100 -> 12.413495 | P16: =G16-R16-2 -> 5 | Q16: =Z16*U16/I16 -> 3.85 | R16: 3 | S16: =1.5*P16 -> 7.5 | T16: =0.5*S16 -> 3.75 | U16: =V16*W16-2 -> 18.48 | V16: =(C16-2*T16)/S16+1 -> 3.2 | W16: =(D16-2*T16)/S16+1 -> 6.4 | X16: =E16*J16*1*C16*D16/(1.7*(V16*W16)) -> 7444.8529 | Y16: 8500 | Z16: 240 | AH16: 8 | AI16: https://diode-system.com/ds-street-83.html
A17: 14 | B17: Инструментальный цех | C17: 36 | D17: 48 | E17: 200 | G17: 11 | H17: =Q17 -> 2.4652778 | I17: =C17*D17 -> 1728 | J17: 1.5 | K17: 0.5 | L17: =H17*I17/1000 -> 4.26 | M17: =L17*K17*J17 -> 3.195 | N17: =TAN(ACOS(0.9))*M17 -> 1.5474091 | O17: =(Y17-X17)/Y17*100 -> -0.30959752 | P17: =G17-R17-2 -> 6 | Q17: =Z17*U17/I17 -> 2.4652778 | R17: 3 | S17: =1.2*P17 -> 7.2 | T17: =0.5*S17 -> 3.6 | U17: =V17*W17+1 -> 23.666667 | V17: =(C17-2*T17)/S17 -> 4 | W17: =(D17-2*T17)/S17 -> 5.6666667 | X17: =E17*J17*1*C17*D17/(1.2*(V17*W17)) -> 19058.824 | Y17: 19000 | Z17: 180 | AH17: 9 | AI17: https://diode-system.com/ds-street-83.html
A18: 15 | B18: Ремонтно-мех цех 1ч | C18: 24 | D18: 16 | E18: 250 | G18: 12 | H18: =Q18 -> 1.71875 | I18: =C18*D18 -> 384 | J18: 1.5 | K18: 0.5 | L18: =H18*I18/1000 -> 0.66 | M18: =L18*K18*J18 -> 0.495 | N18: =TAN(ACOS(0.9))*M18 -> 0.23973944 | O18: =(Y18-X18)/Y18*100 -> 11.764706 | P18: =G18-R18-1 -> 8 | Q18: =Z18*U18/I18 -> 1.71875 | R18: 3 | S18: =0.5*P18 -> 4 | T18: =0.5*S18 -> 2 | U18: =V18*W18 -> 12 | V18: =(C18-2*T18)/S18-1 -> 4 | W18: =(D18-2*T18)/S18 -> 3 | X18: =E18*J18*1*C18*D18/(1.7*(V18*W18)) -> 7058.8235 | Y18: 8000 | Z18: 55 | AH18: 10 | AI18: https://diode-system.com/ds-street-83.html
B19: Ремонтно-мех цех 2ч | C19: 16 | D19: 24 | E19: 250 | G19: 12 | H19: =Q19 -> 1.71875 | I19: =C19*D19 -> 384 | J19: 1.5 | K19: 0.5 | L19: =H19*I19/1000 -> 0.66 | M19: =L19*K19*J19 -> 0.495 | N19: =TAN(ACOS(0.9))*M19 -> 0.23973944 | O19: =(Y19-X19)/Y19*100 -> 11.764706 | P19: =G19-R19-1 -> 8 | Q19: =Z19*U19/I19 -> 1.71875 | R19: 3 | S19: =0.5*P19 -> 4 | T19: =0.5*S19 -> 2 | U19: =V19*W19 -> 12 | V19: =(C19-2*T19)/S19 -> 3 | W19: =(D19-2*T19)/S19-1 -> 4 | X19: =E19*J19*1*C19*D19/(1.7*(V19*W19)) -> 7058.8235 | Y19: 8000 | Z19: 55 | AH19: 11 | AI19: https://diode-system.com/ds-street-lv-150.html
B20: Сварочное отделение | C20: 8 | D20: 8 | E20: 200 | G20: 12 | H20: =Q20 -> 2.5 | I20: =C20*D20 -> 64 | J20: 1.5 | K20: 0.5 | L20: =H20*I20/1000 -> 0.16 | M20: =L20*K20*J20 -> 0.12 | N20: =TAN(ACOS(0.9))*M20 -> 0.058118653 | O20: =(Y20-X20)/Y20*100 -> 5.8823529 | P20: =G20-R20-1 -> 8 | Q20: =Z20*U20/I20 -> 2.5 | R20: 3 | S20: =0.5*P20 -> 4 | T20: =0.5*S20 -> 2 | U20: =V20*W20+1 -> 2 | V20: =(C20-2*T20)/S20 -> 1 | W20: =(D20-2*T20)/S20 -> 1 | X20: =E20*J20*1*C20*D20/(1.7*(V20*W20)) -> 11294.118 | Y20: 12000 | Z20: 80 | AH20: 12 | AI20: https://terra-led.kz/svetilnik_aysberg_ip65/svetilnik-aysberg-mini-20-vt-5000-lm-ip65-analog-lsp-1kh36/
B21: освещение территории | C21: 560 | D21: 340 | E21: 10 | G21: 13 | H21: =Q21 -> 1.5902133 | I21: =C21*D21 -> 190400 | J21: 1.5 | K21: 0.5 | L21: =H21*I21/1000 -> 302.77662 | M21: =L21*K21*J21 -> 227.08246 | N21: =TAN(ACOS(0.9))*M21 -> 109.98106 | O21: =(Y21-X21)/Y21*100 -> 94.751686 | P21: =G21-R21-2 -> 8 | Q21: =Z21*U21/I21 -> 1.5902133 | R21: 3 | S21: =1.45*P21 -> 11.6 | T21: =0.7*S21 -> 8.12 | U21: =V21*W21+8 -> 1288.4111 | V21: =(C21-2*T21)/S21-1 -> 45.875862 | W21: =(D21-2*T21)/S21 -> 27.910345 | X21: =E21*J21*1*C21*D21/(1.7*(V21*W21)) -> 1312.0786 | Y21: 25000 | Z21: 235 | AH21: 13 | AI21: https://diode-system.com/ds-street-60.html
B22: ИТОГО | L22: =SUM(L4:L21) -> 359.38224 | M22: =SUM(M4:M21) -> 271.95291 | N22: =TAN(ACOS(0.9))*M22 -> 131.7128 | AH22: 14 | AI22: https://diode-system.com/ds-street-83.html
M23: =SUM(M18:M20) -> 1.11 | N23: =SUM(N18:N20) -> 0.53759754 | AH23: 15 | AI23: https://diode-system.com/ds-street-lv-150.html
AH24: Терр. | AI24: https://promled.com/groza-300-l-v2-5000k-155×70gr/
I25: =SUM(I4:I15) -> 22464
I28: =10*1*22307*0.3/600 -> 111.535

Sheet 0,4
A1: Таблица 3.1
A2: Электрические нагрузки завода до 1000В
A3: Исходные данные | I3: Расчетные величины | K3: Эффективн. число эл.приемн. nэ | L3: Коэф. расчетной нагрузки Кр | M3: Расчетная мощность | P3: Ток | T3: Силовой сухой трансформатор ТСЛ-1600/10/0,4
A4: По заданию технологов | F4: По справочным данным | I4: Активная мощность | J4: Реактивная, | M4: Активная Р мах | N4: Реактивная, Qмах | O4: Полная, Sмах
A5: Наименование ЭП | B5: Кол-воЭП, шт n | C5: Установленная мощность, кВт | F5: Коэффициент использов Ки | G5: соs | H5: tq
C6: одного ЭП, Рмин | D6: одного ЭП, Рмак | E6: общая Р=n*p | I6: Рпр=Ки*р кВт | J6: Qпр=Ки*р*tg, кВАр | M6: кВт | N6: кВАр | O6: кВА
A7: 2 | B7: 3 | C7: 4 | E7: 5 | F7: 6 | G7: 7 | H7: 9 | I7: 8 | J7: 9 | K7: 10 | L7: 11 | M7: 12 | N7: 13 | O7: 14 | P7: 15
A8: 1. Главный корпус (сборочный цех)
A9: Силовая нагрузка | B9: 80 | C9: 5 | D9: 110 | E9: 2200 | F9: 0.42 | G9: 0.7 | H9: =TAN(ACOS(G9)) -> 1.0202041 | I9: =E9*F9 -> 924 | J9: =I9*H9 -> 942.66855 | K9: =2*E9/D9 -> 40 | L9: 0.7 | M9: =I9*L9 -> 646.8 | N9: =J9 -> 942.66855 | O9: =SQRT(POWER(M9, 2)+POWER(N9, 2)) -> 1143.2297
A10: Электрич.освещ. | E10: =СВЕТ!L4 -> 4.586596 | I10: =M10 -> 4.1738023 | J10: =N10 -> 2.0214647 | M10: =СВЕТ!M4 -> 4.1738023 | N10: =СВЕТ!N4 -> 2.0214647 | O10: =SQRT(POWER(M10, 2)+POWER(N10, 2)) -> 4.6375581 | U10: Рр | V10: в=бета | W10: Sнт | X10: nt | Y10: дельтаN | AA10: m | AC10: Qp
A11: Итого | B11: =B9 -> 80 | C11: =C9 -> 5 | D11: =D9 -> 110 | E11: =SUM(E9:E10) -> 2204.5866 | F11: =I11/E11 -> 0.42101943 | G11: =COS(ATAN(H11)) -> 0.70084377 | H11: =J11/I11 -> 1.0177943 | I11: =SUM(I9:I10) -> 928.1738 | J11: =SUM(J9:J10) -> 944.69002 | K11: 40 | L11: 0.7 | M11: =SUM(M9:M10) -> 650.9738 | N11: =SUM(N9:N10) -> 944.69002 | O11: =SQRT(POWER(M11, 2)+POWER(N11, 2)) -> 1147.2603 | P11: =O11/(1.73*0.38) -> 1745.148 | U11: =M71 -> 7637.6104 | V11: 0.7 | W11: 1600 | X11: =U11/(V11*W11) -> 6.819295 | Y11: 0.17 | Z11: =X11+Y11 -> 6.989295 | AA11: 0 | AB11: =Z11+AA11 -> 6.989295
A12: 2. Механосборочный цех | W12: Qнк1
A13: Силовая нагрузка | B13: 160 | C13: 3 | D13: 65 | E13: 3000 | F13: 0.4 | G13: 0.78 | H13: =TAN(ACOS(G13)) -> 0.80228143 | I13: =E13*F13 -> 1200 | J13: =I13*H13 -> 962.73771 | K13: =2*E13/D13 -> 92.307692 | L13: 0.7 | M13: =I13*L13 -> 840 | N13: =J13 -> 962.73771 | O13: =SQRT(POWER(M13, 2)+POWER(N13, 2)) -> 1277.6791 | S13: Компенсация общая | T13: =AB11 -> 6.989295 | V13: =SQRT(POWER(AB11*V11*W11, 2)-POWER(U25, 2)) -> 1715.9995 | W13: =N71-V13 -> 6563.0986
A14: Электрич.освещ. | E14: =СВЕТ!L5 -> 7.1366083 | I14: =M14 -> 6.4943135 | J14: =N14 -> 3.1453396 | M14: =СВЕТ!M5 -> 6.4943135 | N14: =СВЕТ!N5 -> 3.1453396 | O14: =SQRT(POWER(M14, 2)+POWER(N14, 2)) -> 7.2159039
A15: Итого | B15: =SUM(B13:B14) -> 160 | C15: =C13 -> 3 | D15: =D13 -> 65 | E15: =SUM(E13:E14) -> 3007.1366 | F15: =I15/E15 -> 0.40121034 | G15: =COS(ATAN(H15)) -> 0.78065173 | H15: =J15/I15 -> 0.80056992 | I15: =SUM(I13:I14) -> 1206.4943 | J15: =SUM(J13:J14) -> 965.88305 | K15: 92 | L15: 0.7 | M15: =SUM(M13:M14) -> 846.49431 | N15: =SUM(N13:N14) -> 965.88305 | O15: =SQRT(POWER(M15, 2)+POWER(N15, 2)) -> 1284.3219 | P15: =O15/(1.73*0.38) -> 1953.6384 | S15: второй этап | T15: К1 | U15: К2 | V15: гамма | X15: Qнк2 | Y15: Q сумма
A16: 3.Литейный цех | T16: 19 | U16: 7 | V16: 0.17 | W16: =V16*AB11*W11 -> 1901.0883 | X16: =N71-W13-W16 -> -185.08877 | Y16: =W13+X16 -> 6378.0098 | Z16: КУ
A17: Силовая нагрузка 0,4кВ | B17: 145 | C17: 2 | D17: 75 | E17: 3500 | F17: 0.37 | G17: 0.7 | H17: =TAN(ACOS(G17)) -> 1.0202041 | I17: =E17*F17 -> 1295 | J17: =I17*H17 -> 1321.1643 | K17: =2*E17/D17 -> 93.333333 | L17: 0.75 | M17: =I17*L17 -> 971.25 | N17: =J17 -> 1321.1643 | O17: =SQRT(POWER(M17, 2)+POWER(N17, 2)) -> 1639.7566 | W17: =W16/AB11 -> 272 | X17: =Y16/AB11 -> 912.53979 | Y17: 6400 | Z17: 300
A18: Электрич.освещ. | E18: =СВЕТ!L6 -> 6.9498382 | I18: =M18 -> 6.3243528 | J18: =N18 -> 3.0630238 | M18: =СВЕТ!M6 -> 6.3243528 | N18: =СВЕТ!N6 -> 3.0630238 | O18: =SQRT(POWER(M18, 2)+POWER(N18, 2)) -> 7.0270586 | W18: =150*9 -> 1350 | X18: =Y16*'Ф-202-90-0,4'!D11/N71 -> 1880.5061
A19: Итого | B19: =SUM(B17:B18) -> 145 | C19: 2 | D19: 75 | E19: =SUM(E17:E18) -> 3506.9498 | F19: =I19/E19 -> 0.37107014 | G19: =COS(ATAN(H19)) -> 0.70091196 | H19: =J19/I19 -> 1.0175997 | I19: =SUM(I17:I18) -> 1301.3244 | J19: =SUM(J17:J18) -> 1324.2273 | M19: =SUM(M17:M18) -> 977.57435 | N19: =SUM(N17:N18) -> 1324.2273 | O19: =SQRT(POWER(M19, 2)+POWER(N19, 2)) -> 1645.9737 | P19: =O19/(1.73*0.38) -> 2503.7629 | X19: =Y16*#REF!/N71 -> #REF!
A20: 4. Компрессорная станция | X20: =Y16*#REF!/N71 -> #REF!
A21: Силовая нагрузка 0,4кВ | B21: 18 | C21: 1 | D21: 16 | E21: 150 | F21: 0.65 | G21: 0.8 | H21: =TAN(ACOS(G21)) -> 0.75 | I21: =E21*F21 -> 97.5 | J21: =I21*H21 -> 73.125 | K21: =2*E21/D21 -> 18.75 | L21: 0.9 | M21: =I21*L21 -> 87.75 | N21: =J21 -> 73.125 | O21: =SQRT(POWER(M21, 2)+POWER(N21, 2)) -> 114.2249
A22: Электрич. освещ. | E22: =СВЕТ!L7 -> 2.9982153 | I22: =M22 -> 2.4735277 | J22: =N22 -> 1.1979841 | M22: =СВЕТ!M7 -> 2.4735277 | N22: =СВЕТ!N7 -> 1.1979841 | O22: =SQRT(POWER(M22, 2)+POWER(N22, 2)) -> 2.7483641
A23: Продолжение таблицы 3.1
A24: Итого | B24: =SUM(B21) -> 18 | C24: =C21 -> 1 | D24: =D21 -> 16 | E24: =SUM(E21:E22) -> 152.99822 | F24: =I24/E24 -> 0.65342937 | G24: =COS(ATAN(H24)) -> 0.80252501 | H24: =J24/I24 -> 0.74342664 | I24: =SUM(I21:I22) -> 99.973528 | J24: =SUM(J21:J22) -> 74.322984 | M24: =SUM(M21:M23) -> 90.223528 | N24: =SUM(N21:N23) -> 74.322984 | O24: =SQRT(POWER(M24, 2)+POWER(N24, 2)) -> 116.89393 | P24: =O24/(1.73*0.38) -> 177.81249 | S24: Коэффициент загрузки | T24: К1 | U24: Pр | V24: Qнк1 | W24: Qт
A25: 5. Котельная станция | S25: 0.7 | T25: 19 | U25: =M71 -> 7637.6104 | W25: =SQRT(POWER(AB11*S25*W27, 2)-POWER(U25, 2)) -> 1715.9995
A26: Силовая нагрузка | B26: 35 | C26: 2 | D26: 8 | E26: 800 | F26: 0.45 | G26: 0.8 | H26: =TAN(ACOS(G26)) -> 0.75 | I26: =E26*F26 -> 360 | J26: =I26*H26 -> 270 | K26: =2*E26/D26 -> 200 | L26: 0.8 | M26: =I26*L26 -> 288 | N26: =J26 -> 270 | O26: =SQRT(POWER(M26, 2)+POWER(N26, 2)) -> 394.77082 | S26: Тип трансформатора | T26: К2 | U26: Гамма | V26: Qнк2 | W26: Мощность трансформатора
A27: Освещение | E27: =СВЕТ!L8 -> 3.555 | I27: =M27 -> 3.1995 | J27: =N27 -> 1.5495886 | M27: =СВЕТ!M8 -> 3.1995 | N27: =СВЕТ!N8 -> 1.5495886 | O27: =SQRT(POWER(M27, 2)+POWER(N27, 2)) -> 3.555 | S27: Масляные | T27: 7 | U27: 0.17 | W27: 1600
A28: Итого | B28: =SUM(B26:B27) -> 35 | C28: 2 | D28: 8 | E28: =SUM(E26:E27) -> 803.555 | F28: =I28/E28 -> 0.45199084 | G28: =COS(ATAN(H28)) -> 0.80089883 | H28: =J28/I28 -> 0.74765959 | I28: =SUM(I26:I27) -> 363.1995 | J28: =SUM(J26:J27) -> 271.54959 | M28: =SUM(M26:M27) -> 291.1995 | N28: =SUM(N26:N27) -> 271.54959 | O28: =SQRT(POWER(M28, 2)+POWER(N28, 2)) -> 398.16621 | P28: =O28/(1.73*0.38) -> 605.6681
A29: 6. Кузнечно-прессовый цех
A30: Силовая нагрузка | B30: 80 | C30: 1 | D30: 65 | E30: 1200 | F30: 0.5 | G30: 0.7 | H30: =TAN(ACOS(G30)) -> 1.0202041 | I30: =E30*F30 -> 600 | J30: =I30*H30 -> 612.12244 | K30: =2*E30/D30 -> 36.923077 | L30: 0.7 | M30: =I30*L30 -> 420 | N30: =J30 -> 612.12244 | O30: =SQRT(POWER(M30, 2)+POWER(N30, 2)) -> 742.35697
A31: Электрич.освещ. | E31: =СВЕТ!L9 -> 4.6684499 | I31: =M31 -> 3.6413909 | J31: =N31 -> 1.7636061 | M31: =СВЕТ!M9 -> 3.6413909 | N31: =СВЕТ!N9 -> 1.7636061 | O31: =SQRT(POWER(M31, 2)+POWER(N31, 2)) -> 4.0459899
A32: Итого | B32: =SUM(B30:B31) -> 80 | C32: 1 | D32: 65 | E32: =SUM(E30:E31) -> 1204.6684 | F32: =I32/E32 -> 0.50108508 | G32: =COS(ATAN(H32)) -> 0.70113215 | H32: =J32/I32 -> 1.0169714 | I32: =SUM(I30:I31) -> 603.64139 | J32: =SUM(J30:J31) -> 613.88604 | M32: =SUM(M30:M31) -> 423.64139 | N32: =SUM(N30:N31) -> 613.88604 | O32: =SQRT(POWER(M32, 2)+POWER(N32, 2)) -> 745.87405 | P32: =O32/(1.73*0.38) -> 1134.5818
A33: 7. Ремонтно-механический цех
A34: Силовая нагрузка | B34: 46 | C34: 1.5 | D34: 40 | E34: 2000 | F34: 0.38 | G34: 0.65 | H34: =TAN(ACOS(G34)) -> 1.1691296 | I34: =E34*F34 -> 760 | J34: =I34*H34 -> 888.53846 | K34: =2*E34/D34 -> 100 | L34: 0.75 | M34: =I34*L34 -> 570 | N34: =J34 -> 888.53846 | O34: =SQRT(POWER(M34, 2)+POWER(N34, 2)) -> 1055.6517
A35: Освещение | E35: =СВЕТ!L10 -> 6.4778443 | I35: =M35 -> 2.5263593 | J35: =N35 -> 1.2235716 | M35: =СВЕТ!M10 -> 2.5263593 | N35: =СВЕТ!N10 -> 1.2235716 | O35: =SQRT(POWER(M35, 2)+POWER(N35, 2)) -> 2.8070658
A36: Итого | B36: =SUM(B34:B35) -> 46 | C36: 1.5 | D36: 40 | E36: =SUM(E34:E35) -> 2006.4778 | F36: =I36/E36 -> 0.38003228 | G36: =COS(ATAN(H36)) -> 0.65072899 | H36: =J36/I36 -> 1.1668607 | I36: =SUM(I34:I35) -> 762.52636 | J36: =SUM(J34:J35) -> 889.76203 | M36: =SUM(M34:M35) -> 572.52636 | N36: =SUM(N34:N35) -> 889.76203 | O36: =SQRT(POWER(M36, 2)+POWER(N36, 2)) -> 1058.0467 | P36: =O36/(1.73*0.38) -> 1609.4413
A37: 8. Термический цех
A38: Силовая нагрузка | B38: 180 | C38: 4 | D38: 150 | E38: 1200 | F38: 0.52 | G38: 0.65 | H38: =TAN(ACOS(G38)) -> 1.1691296 | I38: =E38*F38 -> 624 | J38: =I38*H38 -> 729.53684 | K38: =2*E38/D38 -> 16 | L38: 0.7 | M38: =I38*L38 -> 436.8 | N38: =J38 -> 729.53684 | O38: =SQRT(POWER(M38, 2)+POWER(N38, 2)) -> 850.30479
A39: Освещение | E39: =СВЕТ!L11 -> 3.52 | I39: =M39 -> 3.2912 | J39: =N39 -> 1.5940009 | M39: =СВЕТ!M11 -> 3.2912 | N39: =СВЕТ!N11 -> 1.5940009 | O39: =SQRT(POWER(M39, 2)+POWER(N39, 2)) -> 3.6568889
A40: Итого | B40: =SUM(B38:B39) -> 180 | C40: 4 | D40: 150 | E40: =SUM(E38:E39) -> 1203.52 | F40: =I40/E40 -> 0.52121377 | G40: =COS(ATAN(H40)) -> 0.6511549 | H40: =J40/I40 -> 1.1655366 | I40: =SUM(I38:I39) -> 627.2912 | J40: =SUM(J38:J39) -> 731.13084 | M40: =SUM(M38:M39) -> 440.0912 | N40: =SUM(N38:N39) -> 731.13084 | O40: =SQRT(POWER(M40, 2)+POWER(N40, 2)) -> 853.36544 | P40: =O40/(1.73*0.38) -> 1298.0916
...

Sheet Ф-202-90-0,4
A1: Таблица 4.4
A2: Результирующие электрические нагрузки цеховых трансформаторных подстанций
A3: Наименование | B3: Коэф. реактивной мощности cos f | C3: Расчетная нагрузка | F3: Кол-во и мощность тр-ров. шт. кВА | G3: Коэфиц загрузки тр-ров | H3: Расчетные послеавар.токи Ip.а А
C4: кВт | D4: кВАр | E4: кВА
C5: Рр | D5: Qp | E5: Sp
A6: ТП-1
A7: 10. Заготовительно-сварочный цех | C7: ='0,4'!M48 -> 866.82127 | D7: ='0,4'!N48 -> 811.3664 | E7: ='0,4'!O48 -> 1187.3056
A8: 3. Литейный цех | C8: ='0,4'!M19 -> 977.57435 | D8: ='0,4'!N19 -> 1324.2273 | E8: ='0,4'!O19 -> 1645.9737
A9: 11. Склад | C9: ='0,4'!M53 -> 49.085417 | D9: ='0,4'!N53 -> 112.74575 | E9: ='0,4'!O53 -> 122.96741
A10: 15. Ремонтно-механический цех | C10: ='0,4'!M69 -> 193.26 | D10: ='0,4'!N69 -> 192.6876 | E10: ='0,4'!O69 -> 272.90646
A11: Итого 0,4кВ без компенсации | B11: =COS(ATAN(D11/E11)) -> 0.71131 | C11: =SUM(C7:C10) -> 2086.741 | D11: =SUM(D7:D10) -> 2441.027 | E11: =SQRT(POWER(C11, 2)+POWER(D11, 2))/1.3 -> 2470.309 | F11: 2*1600 | G11: =E11/(2*1600) -> 0.77197157
A12: Компенсация | D12: -1800 | M12: =-'0,4'!Y17*'Ф-202-90-0,4'!D11/'0,4'!N71 -> -1886.9897
A13: Итого с компенсацией | B13: =COS(ATAN(D13/E13)) -> 0.95948749 | C13: =SUM(C11:C12) -> 2086.741 | D13: =SUM(D11:D12) -> 641.02704 | E13: =SQRT(POWER(C13, 2)+POWER(D13, 2)) -> 2182.9805 | G13: =E13/(2*1600) -> 0.6821814 | H13: =E13/(1.73*0.4*2) -> 1577.298
A14: Потери в трансформаторах | C14: ='Потери цех тр-ров'!G9 -> 11.878629 | D14: ='Потери цех тр-ров'!H9 -> 76.675661
A15: Итого 10кВ по ТП-1 | B15: =COS(ATAN(D15/E15)) -> 0.9514281 | C15: =SUM(C13:C14) -> 2098.6197 | D15: =SUM(D13:D14) -> 717.7027 | E15: =SQRT(POWER(C15, 2)+POWER(D15, 2)) -> 2217.9499 | G15: =E15/(2*1600) -> 0.69310934 | H15: =E15/(1.73*10*2) -> 64.102598
A16: ТП-2
A17: 2. Механосборочный цех | C17: ='0,4'!M15 -> 846.49431 | D17: ='0,4'!N15 -> 965.88305 | E17: ='0,4'!O15 -> 1284.3219
A18: 7. Ремонтно-механический цех | C18: ='0,4'!M36 -> 572.52636 | D18: ='0,4'!N36 -> 889.76203 | E18: ='0,4'!O36 -> 1058.0467
A19: 9. Насосная станция | C19: ='0,4'!M44 -> 413.82971 | D19: ='0,4'!N44 -> 387.49871 | E19: ='0,4'!O44 -> 566.93058
A20: Освещение территории | C20: ='0,4'!M70 -> 1.11 | D20: ='0,4'!N70 -> 0.23973944 | E20: ='0,4'!O70 -> 1.1355946
A21: 5. Котельная станция | C21: ='0,4'!M28 -> 291.1995 | D21: ='0,4'!N28 -> 271.54959 | E21: ='0,4'!O28 -> 398.16621 | M21: =-'0,4'!Y17*'Ф-202-90-0,4'!D22/'0,4'!N71 -> -1944.1214
A22: Итого 0,4 без компенсации | B22: =COS(ATAN(D22/E22)) -> 0.70960057 | C22: =SUM(C17:C21) -> 2125.1599 | D22: =SUM(D17:D21) -> 2514.9331 | E22: =SQRT(POWER(C22, 2)+POWER(D22, 2))/1.3 -> 2532.7667 | F22: 2*1600 | G22: =E22/(2*1600) -> 0.7914896
A23: Компенсация | D23: -1900
A24: Итого с компенсацией | C24: =SUM(C22:C23) -> 2125.1599 | D24: =SUM(D22:D23) -> 614.93312 | E24: =SQRT(POWER(C24, 2)+POWER(D24, 2)) -> 2212.3398 | G24: =E24/(2*1600) -> 0.69135618 | H24: =E24/(1.73*0.4*2) -> 1598.5114
A25: Потери в трансформаторах | C25: ='Потери цех тр-ров'!G10 -> 12.086561 | D25: ='Потери цех тр-ров'!H10 -> 77.885443
A26: Итого 10кВ по ТП-1 | B26: =COS(ATAN(D26/E26)) -> 0.95559766 | C26: =SUM(C24:C25) -> 2137.2464 | D26: =SUM(D24:D25) -> 692.81857 | E26: =SQRT(POWER(C26, 2)+POWER(D26, 2)) -> 2246.7354 | G26: =E26/(2*1600) -> 0.70210481 | H26: =E26/(1.73*10*2) -> 64.934549
A27: ТП-3
A28: 6. Кузнечно-прессовый цех | C28: ='0,4'!M32 -> 423.64139 | D28: ='0,4'!N32 -> 613.88604 | E28: ='0,4'!O32 -> 745.87405
A29: 12. Административный бытовой корпус | C29: ='0,4'!M57 -> 214.1082 | D29: ='0,4'!N57 -> 188.54955 | E29: ='0,4'!O57 -> 285.29503
A30: 8. Термический цех | C30: ='0,4'!M40 -> 440.0912 | D30: ='0,4'!N40 -> 731.13084 | E30: ='0,4'!O40 -> 853.36544 | M30: =-'0,4'!Y17*'Ф-202-90-0,4'!D31/'0,4'!N71 -> -1185.4945
A31: Итого 0,4 без компенсации | B31: =COS(ATAN(D31/E31)) -> 0.68499399 | C31: =SUM(C28:C30) -> 1077.8408 | D31: =SUM(D28:D30) -> 1533.5664 | E31: =SQRT(POWER(C31, 2)+POWER(D31, 2))/1.3 -> 1441.8854 | F31: 1*1600 | G31: =E31/(1*1600) -> 0.90117839
A32: Компенсация | D32: -1300
A33: Итого с компенсацией | C33: =SUM(C31:C32) -> 1077.8408 | D33: =SUM(D31:D32) -> 233.56643 | E33: =SQRT(POWER(C33, 2)+POWER(D33, 2)) -> 1102.8572 | G33: =E33/(1*1600) -> 0.68928576 | H33: =E33/(1.73*0.4*2) -> 796.86216
A34: Потери в трансформаторах | C34: ='Потери цех тр-ров'!G11 -> 9.9393953 | D34: ='Потери цех тр-ров'!H11 -> 61.611027
A35: Итого 10кВ по ТП-1 | B35: =COS(ATAN(D35/E35)) -> 0.96737647 | C35: =SUM(C33:C34) -> 1087.7802 | D35: =SUM(D33:D34) -> 295.17746 | E35: =SQRT(POWER(C35, 2)+POWER(D35, 2)) -> 1127.1182 | G35: =E35/(1*1600) -> 0.70444888 | H35: =E35/(1.73*10*2) -> 32.575671
A36: ТП-4
A37: 4. Компрессорная станция | C37: ='0,4'!M24 -> 90.223528 | D37: ='0,4'!N24 -> 74.322984 | E37: ='0,4'!O24 -> 116.89393
A38: 1. Главный корпус (сборочный цех) | C38: ='0,4'!M11 -> 650.9738 | D38: ='0,4'!N11 -> 944.69002 | E38: ='0,4'!O11 -> 1147.2603
A39: 13. Транспортный цех | C39: ='0,4'!M61 -> 210.0464 | D39: ='0,4'!N61 -> 184.01105 | E39: ='0,4'!O61 -> 279.2482
A40: 14. Инструментальный цех | C40: ='0,4'!M65 -> 1188.795 | D40: ='0,4'!N65 -> 586.54741 | E40: ='0,4'!O65 -> 1325.6211
...

Sheet Защ. аппаратура 0,4кВ
A1: Выбор выключателей и предохранителей к узлам питания 0,4 кВ
A2: № | B2: Наименование | C2: Pн, кВт | D2: Uн, кВ | E2: Кп | F2: КПД, % | G2: Cos f | H2: Ки | I2: Iра, А | J2: Iн, А | K2: Iпуск, А | L2: Iпик, А | M2: Iт.р. (Iпл.в), А | N2: Iэ.р, А | O2: Тип и параметры выключателя
O3: Тип | P3: Iт.р., А | Q3: Iэ.р., А
A4: 1 | B4: Ввод №1 | C4: 55 | D4: 0.38 | E4: 6.7 | F4: 90 | G4: 0.5 | H4: =ЦЕХ!E39 -> 0.21963155 | I4: ='Ф-202-90-0,4'!E45/(1.73*0.38)/2 -> 1738.3796 | J4: =C4/(1.73*D4*G4*(F4/100)) -> 185.91759 | K4: =J4*E4 -> 1245.6478 | L4: =K4+(I4-H4*J4) -> 2943.194 | M4: =1.1*I4 -> 1912.2175 | N4: =1.25*L4 -> 3678.9925 | O4: Электрон 340В Про | P4: 4000 | Q4: 5000
A5: 2 | B5: Ввод №2 | C5: 55 | D5: 0.38 | E5: 6.7 | F5: 90 | G5: 0.5 | H5: =H4 -> 0.21963155 | I5: =I4 -> 1738.3796 | J5: =C5/(1.73*D5*G5*(F5/100)) -> 185.91759 | K5: =J5*E5 -> 1245.6478 | L5: =K5+(I5-H5*J5) -> 2943.194 | M5: =1.1*I5 -> 1912.2175 | N5: =1.25*L5 -> 3678.9925 | O5: Электрон 340В Про | P5: 4000 | Q5: 5000
A6: 3 | B6: Секционный | C6: 55 | D6: 0.38 | E6: 6.7 | F6: 90 | G6: 0.5 | H6: =H5 -> 0.21963155 | I6: =I5/2 -> 869.18978 | J6: =C6/(1.73*D6*G6*(F6/100)) -> 185.91759 | K6: =J6*E6 -> 1245.6478 | L6: =K6+(I6-H6*J6) -> 2074.0043 | M6: =1.1*I6 -> 956.10876 | N6: =1.25*L6 -> 2592.5053 | O6: Emax E1N | P6: 2900 | Q6: 3500
A7: 4 | B7: ШР-1 | C7: 20 | D7: 0.38 | E7: 6.7 | F7: 90 | G7: 0.65 | H7: =ЦЕХ!E12 -> 0.17 | I7: =ЦЕХ!P12 -> 91.797664 | J7: =C7/(1.73*D7*G7*(F7/100)) -> 52.00492 | K7: =J7*E7 -> 348.43296 | L7: =K7+(I7-H7*J7) -> 431.38979 | M7: =1.1*I7 -> 100.97743 | N7: =1.25*L7 -> 539.23724 | O7: ПН2-250 | P7: 80 | Q7: -
A8: 5 | B8: ШР-2 | C8: 30 | D8: 0.38 | E8: 5 | F8: 80 | G8: 0.65 | H8: =ЦЕХ!E18 -> 0.12 | I8: =ЦЕХ!P18 -> 128.77324 | J8: =C8/(1.73*D8*G8*(F8/100)) -> 87.758302 | K8: =J8*E8 -> 438.79151 | L8: =K8+(I8-H8*J8) -> 557.03376 | M8: =1.1*I8 -> 141.65057 | N8: =1.25*L8 -> 696.2922 | O8: ПН2-250 | P8: 80 | Q8: -
A9: 6 | B9: ШР-3 | C9: 12 | D9: 0.38 | E9: 5 | F9: 80 | G9: 0.65 | H9: =ЦЕХ!E22 -> 0.12 | I9: =ЦЕХ!P22 -> 17.770234 | J9: =C9/(1.73*D9*G9*(F9/100)) -> 35.103321 | K9: =J9*E9 -> 175.5166 | L9: =K9+(I9-H9*J9) -> 189.07444 | M9: =1.1*I9 -> 19.547257 | N9: =1.25*L9 -> 236.34305 | O9: ПН2-250 | P9: 80 | Q9: -
A10: 7 | B10: ШР-4 | C10: 7.5 | D10: 0.38 | E10: 5 | F10: 80 | G10: 0.65 | H10: =ЦЕХ!E27 -> 0.12 | I10: =ЦЕХ!P27 -> 100.88971 | J10: =C10/(1.73*D10*G10*(F10/100)) -> 21.939575 | K10: =J10*E10 -> 109.69788 | L10: =K10+(I10-H10*J10) -> 207.95483 | M10: =1.1*I10 -> 110.97868 | N10: =1.25*L10 -> 259.94354 | O10: ПН2-250 | P10: 25 | Q10: -
A11: 8 | B11: ШР-5 | C11: 30 | D11: 0.38 | E11: 6.7 | F11: 90 | G11: 0.6 | H11: =ЦЕХ!E34 -> 1 | I11: =ЦЕХ!P34 -> 74.00217 | J11: =C11/(1.73*D11*G11*(F11/100)) -> 84.507994 | K11: =J11*E11 -> 566.20356 | L11: =K11+(I11-H11*J11) -> 555.69774 | M11: =1.1*I11 -> 81.402387 | N11: =1.25*L11 -> 694.62217 | O11: ПН2-250 | P11: 25 | Q11: -
A14: № | B14: Наименование | C14: Pн, кВт | D14: Кп | E14: КПД, % | F14: cosφ | G14: α | H14: Iнэп, А | I14: Iпуск, А | J14: Iпл.в, Iн | K14: Iпл.в, Iп | L14: Марка | M14: Iпл.в, А | N14: Iэ.р, А | O14: Тип магн. Пускателя | P14: Тип предохранителя | Q14: Iсраб, А
A15: 1 | B15: Токарные автоматы (6-8) | C15: 10 | D15: 5 | E15: 90 | F15: 0.65 | G15: 1.6 | H15: =C15/(1.73*0.38*F15*(E15/100)) -> 26.00246 | I15: =H15*D15 -> 130.0123 | J15: =1.1*H15 -> 28.602706 | K15: =1.25*I15 -> 162.51537 | L15: ВА13-100 | M15: 80 | N15: 320 | O15: ПМЛ-322 | P15: EKF ППН-35/200 | Q15: 200
A16: 2 | B16: Зубофрезерные станки (9-11) | C16: 21 | D16: 5 | E16: 90 | F16: 0.65 | G16: 1.6 | H16: =C16/(1.73*0.38*F16*(E16/100)) -> 54.605166 | I16: =H16*D16 -> 273.02583 | J16: =1.1*H16 -> 60.065682 | K16: =1.25*I16 -> 341.28229 | L16: ВА13-100 | M16: 80 | N16: 320 | O16: ПМЛ-322 | P16: EKF ППН-39/350 | Q16: 350
A17: 3 | B17: Круглошлифовальные станки (12-13) | C17: 5 | D17: 5 | E17: 90 | F17: 0.5 | G17: 1.6 | H17: =C17/(1.73*0.38*F17*(E17/100)) -> 16.901599 | I17: =H17*D17 -> 84.507994 | J17: =1.1*H17 -> 18.591759 | K17: =1.25*I17 -> 105.63499 | L17: ВА13-100 | M17: 80 | N17: 320 | O17: ПМЛ-322 | P17: EKF ППН-33/125 | Q17: 125
A18: 4 | B18: Заточные станки (15-17) | C18: 1.5 | D18: 6.7 | E18: 90 | F18: 0.5 | G18: 1.6 | H18: =C18/(1.73*0.38*F18*(E18/100)) -> 5.0704797 | I18: =H18*D18 -> 33.972214 | J18: =1.1*H18 -> 5.5775276 | K18: =1.25*I18 -> 42.465267 | L18: ВА51-25 | M18: 8 | N18: 80 | O18: ПМЛ-122 | P18: EKF ППН-33/50 | Q18: 50
A19: 5 | B19: Токарные станки (25) | C19: 12 | D19: 6.7 | E19: 90 | F19: 0.5 | G19: 1.6 | H19: =C19/(1.73*0.38*F19*(E19/100)) -> 40.563837 | I19: =H19*D19 -> 271.77771 | J19: =1.1*H19 -> 44.620221 | K19: =1.25*I19 -> 339.72214 | L19: ВА13-100 | M19: 80 | N19: 320 | O19: ПМЛ-322 | P19: EKF ППН-39/350 | Q19: 350
A20: 6 | B20: Плоскошлифовальные станки (26,27) | C20: 17.2 | D20: 5 | E20: 90 | F20: 0.5 | G20: 1.6 | H20: =C20/(1.73*0.38*F20*(E20/100)) -> 58.1415 | I20: =H20*D20 -> 290.7075 | J20: =1.1*H20 -> 63.95565 | K20: =1.25*I20 -> 363.38438 | L20: ВА13-100 | M20: 80 | N20: 320 | O20: ПМЛ-322 | P20: EKF ППН-39/350 | Q20: 350
A21: 7 | B21: Краны мостовые (38) | C21: 30 | D21: 6.7 | E21: 90 | F21: 0.5 | G21: 1.6 | H21: =C21/(1.73*0.38*F21*(E21/100)) -> 101.40959 | I21: =H21*D21 -> 679.44428 | J21: =1.1*H21 -> 111.55055 | K21: =1.25*I21 -> 849.30534 | L21: ВА51-33 | M21: 125 | N21: 1000 | O21: ПМЛ-622 | P21: EKF ППН-41/1000 | Q21: 1000
A22: 8 | B22: Токарные станки (20-24) | C22: 12 | D22: 5 | E22: 90 | F22: 0.5 | G22: 1.6 | H22: =C22/(1.73*0.38*F22*(E22/100)) -> 40.563837 | I22: =H22*D22 -> 202.81919 | J22: =1.1*H22 -> 44.620221 | K22: =1.25*I22 -> 253.52398 | L22: ВА13-100 | M22: 80 | N22: 320 | O22: ПМЛ-322 | P22: IEK ППНИ-35/250 | Q22: 250
A23: 9 | B23: Сверильные станки (18,19) | C23: 3.4 | D23: 5 | E23: 90 | F23: 0.5 | G23: 1.6 | H23: =C23/(1.73*0.38*F23*(E23/100)) -> 11.493087 | I23: =H23*D23 -> 57.465436 | J23: =1.1*H23 -> 12.642396 | K23: =1.25*I23 -> 71.831795 | L23: ВА13-100 | M23: 80 | N23: 320 | O23: ПМЛ-322 | P23: EKF ППН-33/100 | Q23: 100
A24: 10 | B24: Строгальные станки (29-30) | C24: 4.5 | D24: 5 | E24: 90 | F24: 0.5 | G24: 1.6 | H24: =C24/(1.73*0.38*F24*(E24/100)) -> 15.211439 | I24: =H24*D24 -> 76.057195 | J24: =1.1*H24 -> 16.732583 | K24: =1.25*I24 -> 95.071494 | L24: ВА13-100 | M24: 80 | N24: 320 | O24: ПМЛ-322 | P24: EKF ППН-33/125 | Q24: 125
A25: 11 | B25: Фрезерные станки (32,34) | C25: 7.5 | D25: 5 | E25: 90 | F25: 0.5 | G25: 1.6 | H25: =C25/(1.73*0.38*F25*(E25/100)) -> 25.352398 | I25: =H25*D25 -> 126.76199 | J25: =1.1*H25 -> 27.887638 | K25: =1.25*I25 -> 158.45249 | L25: ВА13-100 | M25: 80 | N25: 320 | O25: ПМЛ-322 | P25: EKF ППН-35/200 | Q25: 200
A26: 12 | B26: Расточные станки (36-37) | C26: 4 | D26: 5 | E26: 90 | F26: 0.5 | G26: 1.6 | H26: =C26/(1.73*0.38*F26*(E26/100)) -> 13.521279 | I26: =H26*D26 -> 67.606396 | J26: =1.1*H26 -> 14.873407 | K26: =1.25*I26 -> 84.507994 | L26: ВА13-100 | M26: 80 | N26: 320 | O26: ПМЛ-322 | P26: EKF ППН-33/100 | Q26: 100
... A33: 19 | B33: Сварочные агрегаты (3-5) | C33: 8.4 | D33: 5 | E33: 80 | F33: 0.6 | G33: 1.6 | H33: =C33/(1.73*0.38*F33*(E33/100)) -> 26.620018 | I33: =H33*D33 -> 133.10009 | J33: =1.1*H33 -> 29.28202 | K33: =1.25*I33 -> 166.37511 | L33: ВА13-100 | M33: 80 | N33: 320 | O33: ПМЛ-322 | P33: EKF ППН-35/200 | Q33: 200
A36: № | B36: Наименование | C36: Iдоп. (Iн) | D36: Кз | E36: Кt | F36: Кп | G36: Iдоп (Iз) | H36: Марки и сечение проводника | I36: Ток
A37: 1 | B37: Токарные автоматы (6-8) | C37: =J15 -> 28.602706 | D37: 1 | E37: 1 | F37: 1 | G37: 80 | H37: ВВГ 4*35 | I37: 127
A38: 2 | B38: Зубофрезерные станки (9-11) | C38: =J16 -> 60.065682 | D38: 1 | E38: 1 | F38: 1 | G38: 80 | H38: ВВГ 4*35 | I38: 127
A39: 3 | B39: Круглошлифовальные станки (12-13) | C39: =J17 -> 18.591759 | D39: 1 | E39: 1 | F39: 1 | G39: 80 | H39: ВВГ 4*35 | I39: 127
A40: 4 | B40: Заточные станки (15-17) | C40: =J18 -> 5.5775276 | D40: 1 | E40: 1 | F40: 1 | G40: 8 | H40: ВВГ 3*2,5 | I40: 27
A41: 5 | B41: Токарные станки (25) | C41: =J19 -> 44.620221 | D41: 1 | E41: 1 | F41: 1 | G41: 80 | H41: ВВГ 4*35 | I41: 127
A42: 6 | B42: Плоскошлифовальные станки (26,27) | C42: =J20 -> 63.95565 | D42: 1 | E42: 1 | F42: 1 | G42: 80 | H42: ВВГ 4*35 | I42: 127
A43: 7 | B43: Краны мостовые (38) | C43: =J21 -> 111.55055 | D43: 1 | E43: 1 | F43: 1 | G43: 125 | H43: ВВГ 4*120 | I43: 280
A44: 8 | B44: Токарные станки (20-24) | C44: =J22 -> 44.620221 | D44: 1 | E44: 1 | F44: 1 | G44: 80 | H44: ВВГ 4*35 | I44: 127
A45: 9 | B45: Сверильные станки (18,19) | C45: =J23 -> 12.642396 | D45: 1 | E45: 1 | F45: 1 | G45: 80 | H45: ВВГ 4*35 | I45: 127
A46: 10 | B46: Строгальные станки (29-30) | C46: =J24 -> 16.732583 | D46: 1 | E46: 1 | F46: 1 | G46: 80 | H46: ВВГ 4*35 | I46: 127
A47: 11 | B47: Фрезерные станки (32,34) | C47: =J25 -> 27.887638 | D47: 1 | E47: 1 | F47: 1 | G47: 80 | H47: ВВГ 4*35 | I47: 127
A48: 12 | B48: Расточные станки (36-37) | C48: =J26 -> 14.873407 | D48: 1 | E48: 1 | F48: 1 | G48: 80 | H48: ВВГ 4*35 | I48: 127
... A55: 19 | B55: Сварочные агрегаты (3-5) | C55: =J33 -> 29.28202 | D55: 1 | E55: 1 | F55: 1 | G55: 80 | H55: ВВГ 4*35 | I55: 127
B58: Узел питания ЩО-1 | C58: Кол-во | D58: Мощность, Вт | E58: Общ. мощность, Вт | F58: Расч. ток, А | G58: Ток тепл. расц-ля, А | H58: Марка АВВ | I58: Ток, А | J58: Тип провода | K58: Ток
...

Sheet Потери цех тр-ров
A4: Таблица 5.1
A5: Потери мощности цеховых трансформаторов
A6: № подстанции | B6: Кол-во тр-ров | C6: Расчетные мощности | G6: Потери расчетные | J6: Таблица 4.1
C7: Рр, кВт | D7: Qр, кВт | E7: Sр кВА | F7: kз.р | J7: Технические данные трансформатора 10/0,4 кВ
G8: Рр, кВт | H8: Qр, квар | J8: Тип трансформатора | K8: Sном | L8: Uк | M8: Ркз | N8: Рхх | O8: I x
A9: ТП-1 | B9: 2 | C9: ='Ф-202-90-0,4'!C11 -> 2086.741 | D9: ='Ф-202-90-0,4'!D13 -> 641.02704 | E9: ='Ф-202-90-0,4'!E13 -> 2182.9805 | F9: =E9/(B9*1600) -> 0.6821814 | G9: =B9*$N$11+POWER(F9, 2)*$M$11 -> 11.878629 | H9: =B9*$J$13+POWER(F9, 2)*$J$14 -> 76.675661 | K9: МВА | L9: % | M9: кВт | N9: кВт | O9: %
A10: ТП-2 | B10: 2 | C10: ='Ф-202-90-0,4'!C22 -> 2125.1599 | D10: ='Ф-202-90-0,4'!D24 -> 614.93312 | E10: ='Ф-202-90-0,4'!E24 -> 2212.3398 | F10: =E10/(B10*1600) -> 0.69135618 | G10: =B10*$N$11+POWER(F10, 2)*$M$11 -> 12.086561 | H10: =B10*$J$13+POWER(F10, 2)*$J$14 -> 77.885443
A11: ТП-3 | B11: 1 | C11: ='Ф-202-90-0,4'!C33 -> 1077.8408 | D11: ='Ф-202-90-0,4'!D33 -> 233.56643 | E11: ='Ф-202-90-0,4'!E33 -> 1102.8572 | F11: =E11/(B11*1600) -> 0.68928576 | G11: =B11*$N$11+POWER(F11, 2)*$M$11 -> 9.9393953 | H11: =B11*$J$13+POWER(F11, 2)*$J$14 -> 61.611027 | J11: ТМ-1600/10/0,4 | K11: 1600 | L11: 6 | M11: 16.5 | N11: 2.1 | O11: 1
A12: ТП-4 | B12: 2 | C12: ='Ф-202-90-0,4'!C43 -> 2140.0387 | D12: ='Ф-202-90-0,4'!D43 -> 689.57146 | E12: ='Ф-202-90-0,4'!E43 -> 2248.3938 | F12: =E12/(B12*1600) -> 0.70262305 | G12: =B12*$N$11+POWER(F12, 2)*$M$11 -> 12.345706 | H12: =B12*$J$13+POWER(F12, 2)*$J$14 -> 79.393199
I13: Qxx | J13: =O11/100*K11 -> 16
I14: Qкз | J14: =L11/100*K11 -> 96

Sheet КАРТОГРАММА
A1: Таблица 5.1
A2: Картограмма нагрузок
A3: № п. п | B3: Наименование цехов | C3: Рр, кВт | D3: Qр, кВт | E3: Ri,м - (Р) | F3: Х,м | G3: Y,м | H3: Рi*X | I3: Pi*Y | J3: Qi*X | K3: Qi*Y | L3: Ri,м - (Q) | M3: освещение | N3: Доля осветит нагр угол
A4: 1 | B4: Главный корпус | C4: ='0,4'!M11 -> 650.9738 | D4: ='0,4'!N11 -> 944.69002 | E4: =C4/SQRT(3.14*1000) -> 11.617126 | F4: 314 | G4: 217 | H4: =F4*C4 -> 204405.77 | I4: =G4*C4 -> 141261.32 | J4: =D4*F4 -> 296632.67 | K4: =D4*G4 -> 204997.73 | L4: =D4/SQRT(3.14*1000) -> 16.858716 | M4: =СВЕТ!M4 -> 4.1738023 | N4: =M4/C4*360 -> 2.3081863
A5: 2 | B5: Механосборочный цех | C5: ='0,4'!M15 -> 846.49431 | D5: ='0,4'!N15 -> 965.88305 | E5: =C5/SQRT(3.14*1000) -> 15.106339 | F5: 179 | G5: 217 | H5: =F5*C5 -> 151522.48 | I5: =G5*C5 -> 183689.27 | J5: =D5*F5 -> 172893.07 | K5: =D5*G5 -> 209596.62 | L5: =D5/SQRT(3.14*1000) -> 17.236922 | M5: =СВЕТ!M5 -> 6.4943135 | N5: =M5/C5*360 -> 2.7619239
A6: 3 | B6: Литейный цех | C6: ='0,4'!M19+'0,4'!M81 -> 16601.574 | D6: ='0,4'!N19+'0,4'!N81 -> 15184.227 | E6: =C6/SQRT(3.14*1000) -> 296.2678 | F6: 390 | G6: 141 | H6: =F6*C6 -> 6474614 | I6: =G6*C6 -> 2340822 | J6: =D6*F6 -> 5921848.6 | K6: =D6*G6 -> 2140976 | L6: =D6/SQRT(3.14*1000) -> 270.97416 | M6: =СВЕТ!M6 -> 6.3243528 | N6: =M6/C6*360 -> 0.13714163
A7: 4 | B7: Компрессорная стацния | C7: ='0,4'!M24+'0,4'!M84 -> 3300.7035 | D7: ='0,4'!N24+'0,4'!N84 -> 2984.923 | E7: =C7/SQRT(3.14*3800) -> 30.216899 | F7: 396 | G7: 223 | H7: =F7*C7 -> 1307078.6 | I7: =G7*C7 -> 736056.89 | J7: =D7*F7 -> 1182029.5 | K7: =D7*G7 -> 665637.83 | L7: =D7/SQRT(3.14*1000) -> 53.268235 | M7: =СВЕТ!M7 -> 2.4735277 | N7: =M7/C7*360 -> 0.26978187
A8: 5 | B8: Котельная станция | C8: ='0,4'!M28 -> 291.1995 | D8: ='0,4'!N28 -> 271.54959 | E8: =C8/SQRT(3.14*1000) -> 5.1966779 | F8: 108 | G8: 217 | H8: =F8*C8 -> 31449.546 | I8: =G8*C8 -> 63190.291 | J8: =D8*F8 -> 29327.356 | K8: =D8*G8 -> 58926.261 | L8: =D8/SQRT(3.14*1000) -> 4.8460102 | M8: =СВЕТ!M8 -> 3.1995 | N8: =M8/C8*360 -> 3.9554326
A9: 6 | B9: Кузнечно-прессовый цех | C9: ='0,4'!M32 -> 423.64139 | D9: ='0,4'!N32 -> 613.88604 | E9: =C9/SQRT(3.14*1000) -> 7.5602048 | F9: 166 | G9: 136 | H9: =F9*C9 -> 70324.471 | I9: =G9*C9 -> 57615.229 | J9: =D9*F9 -> 101905.08 | K9: =D9*G9 -> 83488.502 | L9: =D9/SQRT(3.14*1000) -> 10.955266 | M9: =СВЕТ!M9 -> 3.6413909 | N9: =M9/C9*360 -> 3.0943642
A10: 7 | B10: Ремонтно-механический цех | C10: ='0,4'!M36 -> 572.52636 | D10: ='0,4'!N36 -> 889.76203 | E10: =C10/SQRT(3.14*1000) -> 10.217171 | F10: 70 | G10: 130 | H10: =F10*C10 -> 40076.845 | I10: =G10*C10 -> 74428.427 | J10: =D10*F10 -> 62283.342 | K10: =D10*G10 -> 115669.06 | L10: =D10/SQRT(3.14*1000) -> 15.878484 | M10: =СВЕТ!M10 -> 2.5263593 | N10: =M10/C10*360 -> 1.5885545
A11: 8 | B11: Термический цех | C11: ='0,4'!M40+'0,4'!M84 -> 3650.5712 | D11: ='0,4'!N40 -> 731.13084 | E11: =C11/SQRT(3.14*1000) -> 65.147237 | F11: 246 | G11: 135 | H11: =F11*C11 -> 898040.52 | I11: =G11*C11 -> 492827.11 | J11: =D11*F11 -> 179858.19 | K11: =D11*G11 -> 98702.663 | L11: =D11/SQRT(3.14*1000) -> 13.047589 | M11: =СВЕТ!M11 -> 3.2912 | N11: =M11/C11*360 -> 0.32456072
A12: 9 | B12: Насосная станция | C12: ='0,4'!M44+'0,4'!M87 -> 1813.8297 | D12: ='0,4'!N44+'0,4'!N87 -> 1542.4987 | E12: =C12/SQRT(3.14*1000) -> 32.369179 | F12: 41 | G12: 205 | H12: =F12*C12 -> 74367.018 | I12: =G12*C12 -> 371835.09 | J12: =D12*F12 -> 63242.447 | K12: =D12*G12 -> 316212.24 | L12: =D12/SQRT(3.14*1000) -> 27.52707 | M12: =СВЕТ!M12 -> 1.0297108 | N12: =M12/C12*360 -> 0.20437193
A13: 10 | B13: Заготовительно-сварочный цех | C13: ='0,4'!M48 -> 866.82127 | D13: ='0,4'!N48 -> 811.3664 | E13: =C13/SQRT(3.14*1000) -> 15.469089 | F13: 163 | G13: 53 | H13: =F13*C13 -> 141291.87 | I13: =G13*C13 -> 45941.527 | J13: =D13*F13 -> 132252.72 | K13: =D13*G13 -> 43002.419 | L13: =D13/SQRT(3.14*1000) -> 14.479454 | M13: =СВЕТ!M13 -> 2.821269 | N13: =M13/C13*360 -> 1.1717027
A14: 11 | B14: Склад | C14: ='0,4'!M53 -> 49.085417 | D14: ='0,4'!N53 -> 112.74575 | E14: =C14/SQRT(3.14*1000) -> 0.87596682 | F14: 265 | G14: 54 | H14: =F14*C14 -> 13007.635 | I14: =G14*C14 -> 2650.6125 | J14: =D14*F14 -> 29877.624 | K14: =D14*G14 -> 6088.2706 | L14: =D14/SQRT(3.14*1000) -> 2.0120342 | M14: =СВЕТ!M14 -> 0.33541667 | N14: =M14/C14*360 -> 2.4599975
A15: 12 | B15: Административный бытовой корпус | C15: ='0,4'!M57 -> 214.1082 | D15: ='0,4'!N57 -> 188.54955 | E15: =C15/SQRT(3.14*1000) -> 3.8209247 | F15: 72 | G15: 53 | H15: =F15*C15 -> 15415.791 | I15: =G15*C15 -> 11347.735 | J15: =D15*F15 -> 13575.568 | K15: =D15*G15 -> 9993.1261 | L15: =D15/SQRT(3.14*1000) -> 3.364811 | M15: =СВЕТ!M15 -> 0.92820248 | N15: =M15/C15*360 -> 1.560673
A16: 13 | B16: Транспортный цех | C16: ='0,4'!M61 -> 210.0464 | D16: ='0,4'!N61 -> 184.01105 | E16: =C16/SQRT(3.14*1000) -> 3.7484387 | F16: 250 | G16: 217 | H16: =F16*C16 -> 52511.6 | I16: =G16*C16 -> 45580.069 | J16: =D16*F16 -> 46002.762 | K16: =D16*G16 -> 39930.398 | L16: =D16/SQRT(3.14*1000) -> 3.283818 | M16: =СВЕТ!M16 -> 3.3264 | N16: =M16/C16*360 -> 5.7011403
A17: 14 | B17: Инструментальный цех | C17: ='0,4'!M65 -> 1188.795 | D17: ='0,4'!N65 -> 586.54741 | E17: =C17/SQRT(3.14*1000) -> 21.214957 | F17: 319 | G17: 137 | H17: =F17*C17 -> 379225.6 | I17: =G17*C17 -> 162864.91 | J17: =D17*F17 -> 187108.62 | K17: =D17*G17 -> 80356.995 | L17: =D17/SQRT(3.14*1000) -> 10.467387 | M17: =СВЕТ!M17 -> 3.195 | N17: =M17/C17*360 -> 0.96753435
A18: 15 | B18: Ремонтно-механический цех | C18: ='0,4'!M69 -> 193.26 | D18: ='0,4'!N69 -> 192.6876 | E18: =C18/SQRT(3.14*1000) -> 3.4488726 | F18: 367 | G18: 53 | H18: =F18*C18 -> 70926.42 | I18: =G18*C18 -> 10242.78 | J18: =D18*F18 -> 70716.348 | K18: =D18*G18 -> 10212.443 | L18: =D18/SQRT(3.14*1000) -> 3.4386576 | M18: =СВЕТ!M18 -> 0.495 | N18: =M18/C18*360 -> 0.92207389
B19: Итого | C19: =SUM(C4:C18) -> 30873.63 | D19: =SUM(D4:D18) -> 26204.458 | H19: =SUM(H4:H18) -> 9924258.2 | I19: =SUM(I4:I18) -> 4740353.2 | J19: =SUM(J4:J18) -> 8489553.9 | K19: =SUM(K4:K18) -> 4083790.6
B20: ЦЭН- центр электрических нагрузок | C20: =SUM(C4:C18) -> 30873.63 | D20: =SUM(D4:D18) -> 26204.458 | E20: =C20/SQRT(3.14*1311.31) -> 481.13859 | F20: =H20/C20 -> 321.44772 | G20: =I20/C20 -> 153.54052 | H20: =SUM(H4:H18) -> 9924258.2 | I20: =SUM(I4:I18) -> 4740353.2 | J20: =SUM(J4:J18) -> 8489553.9 | K20: =SUM(K4:K18) -> 4083790.6 | L20: =D20/SQRT(3.14*1311.31) -> 408.37362 | M20: =#REF! -> #REF! | N20: =M20/C20*360 -> #REF! | P20: =C24*(D24/C24-TAN(ACOS(0.98))) -> -7427.7356
C24: =C20*(D20/C20-TAN(ACOS(0.99))) -> 21805.204 | D24: -3000 | E24: 2150 | G24: =SQRT(POWER(C20, 2)+POWER(D20, 2)) -> 40495.119 | H24: =0.7*G24 -> 28346.584 | L24: =C19*(D19/C19-TAN(ACOS(0.98))) -> 19935.3 | M24: 6378 | N24: =L24-M24 -> 13557.3

Sheet Ф202-90-10кВ
A1: Таблица 19
A2: Результирующие электрические нагрузки ГПП 110/10 кВ
A3: Наименование узла | B3: Коэф. реактивной мощности cos f | C3: Расчетная нагрузка | F3: Количество и мощность трансформ. шт. кВА | G3: Расчетный послеавар ток Ip A
C4: кВт | D4: кВАр | E4: кВА
C5: Рр | D5: Qp | E5: Sp
A6: РП-1
A7: АД-10кВ | C7: 1400 | D7: ='0,4'!N87 -> 1155 | E7: ='0,4'!O87 -> 1814.9449
A8: ДСП-10кВ | C8: 15624 | D8: ='0,4'!N81 -> 13860 | E8: ='0,4'!O81 -> 20885.616 | I8: =D15/C15 -> 0.61636791 | J8: =SQRT(1-K8*K8) -> 0.14106736 | K8: 0.99
A9: СД-10кВ | C9: 3210 | D9: ='0,4'!N84 -> 2910.6 | E9: ='0,4'!O84 -> 4333.4483 | I9: =C15*(I8-J8) -> 13171.695
A10: ТП-1 | C10: 2100.71 | D10: ='Ф-202-90-0,4'!D15 -> 717.7027 | E10: ='Ф-202-90-0,4'!E15 -> 2217.9499 | F10: 2x1600
A11: ТП-2 | C11: 2138.12 | D11: ='Ф-202-90-0,4'!D26 -> 692.81857 | E11: ='Ф-202-90-0,4'!E26 -> 2246.7354 | F11: 2x1600
A12: ТП-3 | C12: 1085.63 | D12: ='Ф-202-90-0,4'!D35 -> 295.17746 | E12: ='Ф-202-90-0,4'!E35 -> 1127.1182 | F12: 1x1600
A13: ТП-4 | C13: 2153.89 | D13: ='Ф-202-90-0,4'!D45 -> 768.96466 | E13: ='Ф-202-90-0,4'!E45 -> 2285.6214 | F13: 2x1600
A15: ЗРУ-10 без компенсации | B15: =COS(ATAN(D15/C15)) -> 0.85128447 | C15: =C7+C8+C9+C10+C11+C12+C13 -> 27712.35 | D15: =D7+D8+D9+D10+D11+D12+D13-3319.26 -> 17081.003 | E15: =SQRT(POWER(C15, 2)+POWER(D15, 2)) -> 32553.572
A16: Компенсация | D16: -13000
A17: Итого ЗРУ-10 | B17: =COS(ATAN(D17/C17)) -> 0.98933004 | C17: =SUM(C15:C16) -> 27712.35 | D17: =SUM(D15:D16) -> 4081.0034 | E17: =SQRT(POWER(C17, 2)+POWER(D17, 2)) -> 28011.229 | G17: =E17/(1.73*10) -> 1619.1462
A18: Итого | B18: =COS(ATAN(D18/C18)) -> 0.98745226 | C18: =SUM(C11, C17) -> 29850.47 | D18: =SUM(D11, D17) -> 4773.8219 | E18: =SQRT(POWER(C18, 2)+POWER(D18, 2)) -> 30229.786 | G18: =E18/(1.73*6) -> 2912.3107
A19: Потери в тр-рах ГПП | C19: ='Потери ГПП'!H6 -> 85.683412 | D19: ='Потери ГПП'!I6 -> 1253.8255 | F19: 2х25000
A20: Итого | B20: =COS(ATAN(D20/C20))+0.02 -> 1.0003253 | C20: =SUM(C18:C19) -> 29936.153 | D20: =SUM(D18:D19) -> 6027.6474 | E20: =SQRT(POWER(C20, 2)+POWER(D20, 2)) -> 30536.958 | G20: =E20/(1.73*110) -> 160.46746
A29: Наименование узла | B29: Коэф. реактивной мощности cos f | C29: Расчетная нагрузка | F29: Количество и мощность трансформ. шт. кВА | G29: Расчетный послеавар ток Ip A
C30: кВт | D30: кВАр | E30: кВА
C31: Рр | D31: Qp | E31: Sp
A32: Двигатели АД | C32: ='0,4'!M84 -> 3210.48 | D32: ='0,4'!N84 -> 2910.6
A33: ТП3 | C33: =#REF! -> #REF! | D33: =#REF! -> #REF! | F33: 2х1000
A34: ТП1-ТП2 | C34: =#REF! -> #REF! | D34: =#REF! -> #REF! | F34: 4х1000
A35: ТП4 | C35: =#REF! -> #REF! | D35: =#REF! -> #REF! | F35: 2х1000
A36: Двигатели СД | C36: ='0,4'!M82 -> 0 | D36: ='0,4'!N82 -> 0
A37: ЗРУ-10 без компенсации | B37: =COS(ATAN(D37/C37)) -> #REF! | C37: =C32+C33+C34+C36+C35 -> #REF! | D37: =D32+D36+D33+D35+D34 -> #REF! | E37: =SQRT(POWER(C37, 2)+POWER(D37, 2)) -> #REF!
A38: Компенсация | D38: -2100
A39: Итого ЗРУ-6 | B39: =COS(ATAN(D39/C39)) -> #REF! | C39: =SUM(C37:C38) -> #REF! | D39: =SUM(D37:D38) -> #REF! | E39: =SQRT(POWER(C39, 2)+POWER(D39, 2)) -> #REF! | G39: =E39/(1.73*6) -> #REF!
A40: Итого | B40: =COS(ATAN(D40/C40)) -> #REF! | C40: =SUM(C38:C39) -> #REF! | D40: =SUM(D37:D38) -> #REF! | E40: =SQRT(POWER(C40, 2)+POWER(D40, 2)) -> #REF! | G40: =E40/(1.73*6) -> #REF!
A41: Потери в тр-рах ГПП | C41: ='Потери ГПП'!H6 -> 85.683412 | D41: ='Потери ГПП'!I6 -> 1253.8255 | F41: 2х10000
A42: Итого на 35 кВ | B42: =COS(ATAN(D42/C42)) -> #REF! | C42: =SUM(C40:C41) -> #REF! | D42: =SUM(D40:D41) -> #REF! | E42: =SQRT(POWER(C42, 2)+POWER(D42, 2)) -> #REF! | G42: =E42/(1.73*35) -> #REF!

Sheet ТЭР
B1: Таблица 6.2
B2: Постоянная часть затрат ПС
B3: Наименование оборудования | C3: Стоимость единицы, тыс. тенге | D3: Первый вариант | F3: Второй вариант | K3: амортизация
D4: Кол-во | E4: Общая стоимость тыс. тенге | F4: Кол-во | G4: Общая стоимость, тыс. тенге | J4: амортиз | K4: =5+9.4 -> 14.4 | L4: =5+9.4 -> 14.4
B5: Трансформаторы ГПП ТДТН-25000/110/10 | C5: 65000 | D5: 2 | E5: =C5*D5 -> 130000 | F5: - | G5: - | J5: 92
B6: Трансформаторы ГПП ТДН-40000/110/10 | C6: 100000 | D6: - | E6: - | F6: 2 | G6: =F6*C6 -> 200000
B7: Реакторы одинарные РТСТ-10-5000 | C7: 2000 | D7: 5 | E7: =C7*D7 -> 10000 | F7: - | G7: - | J7: 55
B8: Реакторы сдвоенные РБАС-10 кВ | C8: 3700 | D8: - | E8: - | F8: 2 | G8: =C8*F8 -> 7400 | J8: аморт иац отчис | K8: =K4/100*E10 -> 59760 | L8: 25
B9: Трансформатор электропечной ТЗП-5000/10 | C9: 55000 | D9: 5 | E9: =C9*D9 -> 275000 | F9: 5 | G9: =C9*F9 -> 275000 | K9: =K4/100*G10 -> 69465.6 | L9: 40
B10: Кап. затраты КS | E10: =SUM(E5:E9) -> 415000 | G10: =SUM(G5:G9) -> 482400
M11: =0.125*M9 -> 0 | O11: =0.125*O9 -> 0
J12: амортизация | K12: =14.4/100 -> 0.144 | M12: =K12*M9 -> 0 | O12: =K12*O9 -> 0
L14: =1154979.9 -> 1154979.9 | M14: =L14*4.2/1000 -> 4850.9156 | N14: 825517.2 | O14: =N14*4.2/1000 -> 3467.1722
M15: =SUM(M11:M14) -> 4850.9156 | O15: =SUM(O11:O14) -> 3467.1722
Q16: 20
B20: Таблица 5.1
B21: Технические данные трансформаторов ГПП
B22: Тип трансформатора | C22: Sном | D22: Uк | E22: Ркз | F22: Рхх | G22: I x
C23: МВА | D23: % | E23: кВт | F23: кВт | G23: %
B24: ТДН-25000/110 | C24: 25000 | D24: 10.5 | E24: 120 | F24: 19 | G24: 0.23
B25: ТДН-40000/110 | C25: 40000 | D25: 10.5 | E25: 170 | F25: 22 | G25: 0.28
B27: расчет потерь | C27: 8760*Pxx | D27: Кз | E27: t | F27: сумма по потерям | G27: стоимость э/э
B28: тр 25000 | C28: =F24*8760 -> 166440 | D28: 0.33 | E28: 7000 | F28: =(C28+E24*POWER(D28, 2)*E28)*2 -> 515832 | G28: =15*F28 -> 7737480 | H28: тыс.тг
B29: тр 40000 | C29: =F25*8760 -> 192720 | D29: 0.52 | E29: 7000 | F29: =(C29+E25*POWER(D29, 2)*E29)*2 -> 1028992 | G29: =15*F29 -> 15434880 | H29: =G28/1000 -> 7737.48
H30: =G29/1000 -> 15434.88
B31: Приведенные затраты | C31: =0.125*M25+K9+H29 -> 77203.08 | D31: 25
C32: =0.125*O25+K10+H30 -> 15434.88 | D32: 40
B34: Эконом эффект , срок окупаем | D34: =G10-E10 -> 67400 | E34: =K9-K8 -> 9705.6 | F34: =D34/E34 -> 6.9444444 | G34: =1/F34 -> 0.144 | L34: 59639 | M34: 86 | N34: =L34/M34 -> 693.47674 | O34: 46.5
L35: 56000 | M35: 86 | N35: =L35/M35 -> 651.16279 | O35: 176
O36: =SUM(O34:O35) -> 222.5 | P36: =O36*N34 -> 154298.58 | Q36: =0.8*P36 -> 123438.86
B37: 17183.55 | C37: =B37*6.87*8760 -> 1.0341267e+09 | D37: =C37*0.001 -> 1034126.7 | F37: =B37*0.05 -> 859.1775
A38: Рр | C38: =B37*8760 -> 150527898 | N38: 66 | O38: =N38*N35 -> 42976.744 | Q38: =0.8*O38 -> 34381.395
B39: 3638.68 | C39: =B39*6.87*8760 -> 2.1898013e+08 | D39: =C39*0.001 -> 218980.13 | Q39: =SUM(Q36:Q38) -> 157820.26
A40: Qp | C40: =B39*8760 -> 31874837 | D40: =C40*0.001 -> 31874.837
A42: Таблица 20
A43: Таблица 20 .Постоянная часть затрат ПС
